Workbook
Name UPDATE: 'Data Sheet'!$E$1

Sheet Summary
B2: Discounted Cash Flow Valuation
B4: Company : Infosys Ltd
B5: Prepared by : Arjit Uttam
B6: Date : March / 2026
B8: Valuation Results :
B10: Equity Value per Share | E10: =DCF!D40 -> 925.21441
B11: Terminal Value | E11: =DCF!D26 -> 474576.83
B12: PV OF FCFF | E12: =DCF!D31 -> 112163.02
B13: PV OF Terminal Value | E13: =DCF!D32 -> 246804.8
B15: Key Insights :

Sheet Assumptions
B2: Assumptions taken:
B4: Macroeconomic Inputs:
B6: Variable | C6: Value | D6: Notes
B7: Risk Free Rate | C7: =WACC!K22 -> 0.06679 | D7: India 10 Year Bonds
B8: Levered Beta | C8: =WACC!K24 -> 0.95584258 | D8: From Comps
B10: Cost of Capital:
B12: Variable | C12: Value
B13: Pre Tax Cost of Debt | C13: =WACC!E22 -> 0.037778997
B14: Tax Rate | C14: =WACC!E23 -> 0.3
B15: WACC | C15: =WACC!K43 -> 0.15638021
B17: Operating Assumptions :
B19: Variable | C19: Value
B20: EBIT Growth Rate | C20: =DCF!D15 -> 0.14260712
B21: Reinvestment Rate | C21: =DCF!E8 -> 0.24110461
B23: Terminal Assumptions :
B25: Variable | C25: Value
B26: Terminal Growth Rate | C26: =DCF!D16 -> 0.055
B29: Disclaimer :
B30: This model is built for learning purposes, and certain assumptions are simplified; therefore, the valuation should be interpreted as indicative rather than precise.

Sheet DCF>

Sheet WACC
B2: Weighted Average Cost of Capital
B4: All figures are in INR unless stated otherwise
B6: Peer Comps
H7: Debt / | I7: Debt / | J7: Levered | K7: Unlevered
B8: Name of the Comp | D8: Country | E8: Total Debt | F8: Total Equity | G8: Tax Rate | H8: Equity | I8: Capital | J8: Beta 2 | K8: Beta 3
B10: TCS | D10: India | E10: ='Beta Comps'!E5 -> 10932 | F10: ='Beta Comps'!F5 -> 871979.34 | G10: 0.3 | H10: =E10/F10 -> 0.012536994 | I10: =E10/(E10+F10) -> 0.012381764 | J10: 1.06 | K10: =J10/(1+(1-G10)*H10) -> 1.0507785
B11: Infosys Ltd | D11: India | E11: ='Beta Comps'!E6 -> 8796 | F11: ='Beta Comps'!F6 -> 506214.48 | G11: 0.3 | H11: =E11/F11 -> 0.017376034 | I11: =E11/(E11+F11) -> 0.017079264 | J11: 0.84 | K11: =J11/(1+(1-G11)*H11) -> 0.82990567
B12: HCL Technologies | D12: India | E12: ='Beta Comps'!E7 -> 6780 | F12: ='Beta Comps'!F7 -> 359576.51 | G12: 0.3 | H12: =E12/F12 -> 0.018855514 | I12: =E12/(E12+F12) -> 0.018506563 | J12: 0.95 | K12: =J12/(1+(1-G12)*H12) -> 0.93762443
B13: Wipro | D13: India | E13: ='Beta Comps'!E8 -> 16163.7 | F13: ='Beta Comps'!F8 -> 207335.47 | G13: 0.3 | H13: =E13/F13 -> 0.077959164 | I13: =E13/(E13+F13) -> 0.072321074 | J13: 0.93 | K13: =J13/(1+(1-G13)*H13) -> 0.88187484
B14: Tech Mahindra | D14: India | E14: ='Beta Comps'!E9 -> 1954.4 | F14: ='Beta Comps'!F9 -> 130551.18 | G14: 0.3 | H14: =E14/F14 -> 0.014970374 | I14: =E14/(E14+F14) -> 0.014749568 | J14: 1.01 | K14: =J14/(1+(1-G14)*H14) -> 0.99952571
F16: Average | G16: =AVERAGE(G10:G14) -> 0.3 | H16: =AVERAGE(H10:H14) -> 0.028339616 | I16: =AVERAGE(I10:I14) -> 0.027007647 | J16: =AVERAGE(J10:J14) -> 0.958 | K16: =AVERAGE(K10:K14) -> 0.93994183
F17: Median | G17: =MEDIAN(G10:G14) -> 0.3 | H17: =MEDIAN(H10:H14) -> 0.017376034 | I17: =MEDIAN(I10:I14) -> 0.017079264 | J17: =MEDIAN(J10:J14) -> 0.95 | K17: =MEDIAN(K10:K14) -> 0.93762443
B20: Cost of Debt | G20: Cost of Equity
B22: Pre Tax Cost of Debt | E22: =413/10932 -> 0.037778997 | G22: Risk Free Rate | K22: 0.06679
B23: Tax Rate | E23: =G17 -> 0.3 | G23: Equity Risk Premium | K23: =Rm!G7-WACC!K22 -> 0.097502308
B24: Post Tax Cost of Debt | E24: =E22*(1-E23) -> 0.026445298 | G24: Levered Beta 4 | K24: =K33 -> 0.95584258
G25: Cost of Equity | K25: =K22+(K23*K24) -> 0.15998686
B28: Capital Structure | G28: Levered Beta
D30: Current | E30: Target | G30: Comp Median Unlevered Beta | K30: =K17 -> 0.93762443
B31: Total Debt | C31: =E11 -> 8796 | D31: =C31/$C$33 -> 0.017079264 | E31: =I16 -> 0.027007647 | G31: Target Debt / Equity | K31: =E35 -> 0.027757306
B32: Market Capitalization | C32: =F11 -> 506214.48 | D32: =C32/$C$33 -> 0.98292074 | E32: =E33-E31 -> 0.97299235 | G32: Tax Rate | K32: =E23 -> 0.3
B33: Total Capital | C33: =C31+C32 -> 515010.48 | D33: =C33/$C$33 -> 1 | E33: =D33 -> 1 | G33: Levered Beta | K33: =K30*(1+(1-K32)*K31) -> 0.95584258
B35: Debt / Equity | D35: =D31/D32 -> 0.017376034 | E35: =E31/E32 -> 0.027757306 | G35: Weighted Average Cost of Capital
B37: Notes: | G37: Cost of Equity | K37: =K25 -> 0.15998686
B38: 1. Tax Rate considered as Marginal Tax Rate for the country | G38: Equity Weight | K38: =E32 -> 0.97299235
B39: 2. Levered beta is based on 5 year monthly data
B40: 3. Unlevered beta = Levered Beta/(1+(1-Tax Rate)*Debt/Equity) | G40: Cost of Debt | K40: =E24 -> 0.026445298
B41: 4. Levered beta = Unlevered Beta*(1+(1-Tax Rate)*Debt/Equity) | G41: Debt Weight | K41: =E31 -> 0.027007647
G43: WACC | K43: =(K37*K38)+(K40*K41) -> 0.15638021

Sheet Data>

Sheet Beta Regression
B2: Regression Beta - 5 Years Monthly
B4: Infosys Ltd Weekly Returns | F4: Nifty Returns | I4: Beta Drifitng | L4: Beta 1 | M4: =SLOPE(D8:D66,G8:G66) -> 0.83788098
L5: Beta 2 | M5: =_xlfn.COVARIANCE.S(D7:D66,G7:G66)/_xlfn.VAR.S(G7:G66) -> 0.83788098
B6: Date | C6: Closing Price | D6: Return | F6: Closing Price | G6: Return | I6: Levered Raw Beta | J6: =M7 -> 0.83788098
B7: 44287 | C7: 1192.26 | F7: 14631.1 | I7: Raw Beta Weight | J7: 0.75 | L7: Beta 3 | M7: =M26 -> 0.83788098
B8: 44317 | C8: 1226.95 | D8: =C8/C7-1 -> 0.029096003 | F8: 15582.8 | G8: =F8/F7-1 -> 0.065046374
B9: 44348 | C9: 1406.63 | D9: =C9/C8-1 -> 0.14644444 | F9: 15721.5 | G9: =F9/F8-1 -> 0.0089008394 | I9: Market Beta | J9: 1 | L9: SUMMARY OUTPUT
B10: 44378 | C10: 1433.05 | D10: =C10/C9-1 -> 0.01878248 | F10: 15763.05 | G10: =F10/F9-1 -> 0.0026428776 | I10: Market Beta Weight | J10: 0.25
B11: 44409 | C11: 1518.43 | D11: =C11/C10-1 -> 0.059579219 | F11: 17132.2 | G11: =F11/F10-1 -> 0.086858191 | L11: Regression Statistics
B12: 44440 | C12: 1490.63 | D12: =C12/C11-1 -> -0.018308384 | F12: 17618.15 | G12: =F12/F11-1 -> 0.028364717 | I12: Adjusted Beta | J12: =(J6*J7)+(J9*J10) -> 0.87841073 | L12: Multiple R | M12: 0.42467809
B13: 44470 | C13: 1484 | D13: =C13/C12-1 -> -0.0044477838 | F13: 17671.65 | G13: =F13/F12-1 -> 0.0030366412 | L13: R Square | M13: 0.18035148
B14: 44501 | C14: 1537.46 | D14: =C14/C13-1 -> 0.036024259 | F14: 16983.2 | G14: =F14/F13-1 -> -0.038957879 | L14: Adjusted R Square | M14: 0.16597168
B15: 44531 | C15: 1694.64 | D15: =C15/C14-1 -> 0.10223355 | F15: 17354.05 | G15: =F15/F14-1 -> 0.021836285 | L15: Standard Error | M15: 0.067608411
B16: 44562 | C16: 1558.6 | D16: =C16/C15-1 -> -0.080276637 | F16: 17339.85 | G16: =F16/F15-1 -> -0.0008182528 | L16: Observations | M16: 59
B17: 44593 | C17: 1540.1 | D17: =C17/C16-1 -> -0.011869627 | F17: 16793.9 | G17: =F17/F16-1 -> -0.031485278
B18: 44621 | C18: 1711.79 | D18: =C18/C17-1 -> 0.11147977 | F18: 17464.75 | G18: =F18/F17-1 -> 0.039946052 | L18: ANOVA
B19: 44652 | C19: 1407.2 | D19: =C19/C18-1 -> -0.17793655 | F19: 17102.55 | G19: =F19/F18-1 -> -0.020738917 | M19: df | N19: SS | O19: MS | P19: F | Q19: Significance F
B20: 44682 | C20: 1349.79 | D20: =C20/C19-1 -> -0.040797328 | F20: 16584.55 | G20: =F20/F19-1 -> -0.030287881 | L20: Regression | M20: 1 | N20: 0.057328208 | O20: 0.057328208 | P20: 12.542003 | Q20: 0.00080105447
B21: 44713 | C21: 1326.25 | D21: =C21/C20-1 -> -0.01743975 | F21: 15780.25 | G21: =F21/F20-1 -> -0.048496944 | L21: Residual | M21: 57 | N21: 0.26054114 | O21: 0.0045708972
B22: 44743 | C22: 1405.91 | D22: =C22/C21-1 -> 0.06006409 | F22: 17158.25 | G22: =F22/F21-1 -> 0.087324345 | L22: Total | M22: 58 | N22: 0.31786935
B23: 44774 | C23: 1354.42 | D23: =C23/C22-1 -> -0.036623966 | F23: 17759.3 | G23: =F23/F22-1 -> 0.035029796
B24: 44805 | C24: 1282.3 | D24: =C24/C23-1 -> -0.053247885 | F24: 17094.35 | G24: =F24/F23-1 -> -0.037442354 | M24: Coefficients | N24: Standard Error | O24: t Stat | P24: P-value | Q24: Lower 95% | R24: Upper 95% | S24: Lower 95.0% | T24: Upper 95.0%
B25: 44835 | C25: 1394.98 | D25: =C25/C24-1 -> 0.087873353 | F25: 18012.2 | G25: =F25/F24-1 -> 0.053693179 | L25: Intercept | M25: -0.0036005818 | N25: 0.0090284254 | O25: -0.39880507 | P25: 0.69152698 | Q25: -0.021679692 | R25: 0.014478528 | S25: -0.021679692 | T25: 0.014478528
B26: 44866 | C26: 1499.46 | D26: =C26/C25-1 -> 0.074897131 | F26: 18758.35 | G26: =F26/F25-1 -> 0.041424701 | L26: X Variable 1 | M26: 0.83788098 | N26: 0.23659136 | O26: 3.5414691 | P26: 0.00080105447 | Q26: 0.36411496 | R26: 1.311647 | S26: 0.36411496 | T26: 1.311647
B27: 44896 | C27: 1383.21 | D27: =C27/C26-1 -> -0.07752791 | F27: 18105.3 | G27: =F27/F26-1 -> -0.03481383
B28: 44927 | C28: 1406.64 | D28: =C28/C27-1 -> 0.01693886 | F28: 17662.15 | G28: =F28/F27-1 -> -0.024476258
B29: 44958 | C29: 1364.27 | D29: =C29/C28-1 -> -0.030121424 | F29: 17303.95 | G29: =F29/F28-1 -> -0.020280657
B30: 44986 | C30: 1309.61 | D30: =C30/C29-1 -> -0.040065383 | F30: 17359.75 | G30: =F30/F29-1 -> 0.0032246973
B31: 45017 | C31: 1148.93 | D31: =C31/C30-1 -> -0.12269302 | F31: 18065 | G31: =F31/F30-1 -> 0.040625585
B32: 45047 | C32: 1209.05 | D32: =C32/C31-1 -> 0.052326948 | F32: 18534.4 | G32: =F32/F31-1 -> 0.025983947
B33: 45078 | C33: 1224.82 | D33: =C33/C32-1 -> 0.013043298 | F33: 19189.05 | G33: =F33/F32-1 -> 0.035320809
B34: 45108 | C34: 1260.06 | D34: =C34/C33-1 -> 0.028771575 | F34: 19753.8 | G34: =F34/F33-1 -> 0.029430847
B35: 45139 | C35: 1334.19 | D35: =C35/C34-1 -> 0.058830532 | F35: 19253.8 | G35: =F35/F34-1 -> -0.025311586
B36: 45170 | C36: 1334.19 | D36: =C36/C35-1 -> 0 | F36: 19638.3 | G36: =F36/F35-1 -> 0.019970084
B37: 45200 | C37: 1271.87 | D37: =C37/C36-1 -> -0.046709989 | F37: 19079.6 | G37: =F37/F36-1 -> -0.028449509
B38: 45231 | C38: 1370 | D38: =C38/C37-1 -> 0.077154112 | F38: 20133.15 | G38: =F38/F37-1 -> 0.055218663
... B66: 46082 | C66: 1248.3 | D66: =C66/C65-1 -> -0.039843089 | F66: 23151.1 | G66: =F66/F65-1 -> -0.080526557

Sheet Beta Comps
B4: S.No. | C4: Name | D4: CMP Rs. | E4: Debt Rs.Cr. | F4: Mar Cap Rs.Cr. | G4: Debt / Eq
B5: 1 | C5: TCS | D5: 2410.5 | E5: 10932 | F5: 871979.34 | G5: 0.1
B6: 2 | C6: Infosys | D6: 1248.3 | E6: 8796 | F6: 506214.48 | G6: 0.11
B7: 3 | C7: HCL Technologies | D7: 1325.4 | E7: 6780 | F7: 359576.51 | G7: 0.1
B8: 4 | C8: Wipro | D8: 197.58 | E8: 16163.7 | F8: 207335.47 | G8: 0.19
B9: 5 | C9: Tech Mahindra | D9: 1332.8 | E9: 1954.4 | F9: 130551.18 | G9: 0.07

Sheet Rm
B2: Return on Markets
B4: Year | C4: Annual
B5: 2000 | C5: -0.1465 | E5: Average Return | G5: =AVERAGE(C5:C30) -> 0.15149231
B6: 2001 | C6: -0.1618 | E6: Dividend Yeild | G6: 0.0128
B7: 2002 | C7: 0.0325 | E7: Total Market Return | G7: =G5+G6 -> 0.16429231
B8: 2003 | C8: 0.719
B9: 2004 | C9: 0.1068
B10: 2005 | C10: 0.3634
B11: 2006 | C11: 0.3983
B12: 2007 | C12: 0.5477
B13: 2008 | C13: -0.5179
B14: 2009 | C14: 0.7576
B15: 2010 | C15: 0.1795
B16: 2011 | C16: -0.2462
B17: 2012 | C17: 0.277
B18: 2013 | C18: 0.0676
B19: 2014 | C19: 0.3139
... B30: 2025 | C30: 0.1051

Sheet Intrinsic Growth
B2: Calcualtion of ROIC | G2: ='Raw FS'!J2 -> 44256 | H2: ='Raw FS'!K2 -> 44621 | I2: ='Raw FS'!L2 -> 44986 | J2: ='Raw FS'!M2 -> 45352 | K2: ='Raw FS'!N2 -> 45717
B4: Current Assets
B5: ='Raw FS'!B33 -> Trade receivables | G5: ='Raw FS'!J33 -> 19294 | H5: ='Raw FS'!K33 -> 22698 | I5: ='Raw FS'!L33 -> 25424 | J5: ='Raw FS'!M33 -> 30193 | K5: ='Raw FS'!N33 -> 31158
B6: ='Raw FS'!B35 -> Loans n Advances | G6: ='Raw FS'!J35 -> 1460 | H6: ='Raw FS'!K35 -> 2491 | I6: ='Raw FS'!L35 -> 3242 | J6: ='Raw FS'!M35 -> 10330 | K6: ='Raw FS'!N35 -> 6717
B7: ='Raw FS'!B36 -> Other asset items | G7: ='Raw FS'!J36 -> 21411 | H7: ='Raw FS'!K36 -> 27528 | I7: ='Raw FS'!L36 -> 34766 | J7: ='Raw FS'!M36 -> 29513 | K7: ='Raw FS'!N36 -> 30149
B8: Total Current Assets | G8: =G5+G6+G7 -> 42165 | H8: =H5+H6+H7 -> 52717 | I8: =I5+I6+I7 -> 63432 | J8: =J5+J6+J7 -> 70036 | K8: =K5+K6+K7 -> 68024
B10: Current Liabilities
B11: ='Raw FS'!B10 -> Trade Payables | G11: ='Raw FS'!J10 -> 2645 | H11: ='Raw FS'!K10 -> 4134 | I11: ='Raw FS'!L10 -> 3865 | J11: ='Raw FS'!M10 -> 3956 | K11: ='Raw FS'!N10 -> 4164
B12: ='Raw FS'!B11 -> Advance from Customers | G12: ='Raw FS'!J11 -> 0 | H12: ='Raw FS'!K11 -> 0 | I12: ='Raw FS'!L11 -> 0 | J12: ='Raw FS'!M11 -> 0 | K12: ='Raw FS'!N11 -> 0
B13: ='Raw FS'!B12 -> Other liability items | G13: ='Raw FS'!J12 -> 22759 | H13: ='Raw FS'!K12 -> 31385 | I13: ='Raw FS'!L12 -> 36637 | J13: ='Raw FS'!M12 -> 36584 | K13: ='Raw FS'!N12 -> 39201
B14: Total Current Liabilities | G14: =G11+G12+G13 -> 25404 | H14: =H11+H12+H13 -> 35519 | I14: =I11+I12+I13 -> 40502 | J14: =J11+J12+J13 -> 40540 | K14: =K11+K12+K13 -> 43365
A16: # | B16: Net Working Capital | G16: =G8-G14 -> 16761 | H16: =H8-H14 -> 17198 | I16: =I8-I14 -> 22930 | J16: =J8-J14 -> 29496 | K16: =K8-K14 -> 24659
B18: Non Current Assets
B19: ='Raw FS'!B16 -> Land | G19: ='Raw FS'!J16 -> 2036 | H19: ='Raw FS'!K16 -> 2065 | I19: ='Raw FS'!L16 -> 2054 | J19: ='Raw FS'!M16 -> 2037 | K19: ='Raw FS'!N16 -> 2079
B20: ='Raw FS'!B17 -> Building | G20: ='Raw FS'!J17 -> 16328 | H20: ='Raw FS'!K17 -> 16761 | I20: ='Raw FS'!L17 -> 16903 | J20: ='Raw FS'!M17 -> 16515 | K20: ='Raw FS'!N17 -> 16376
B21: ='Raw FS'!B18 -> Plant Machinery | G21: ='Raw FS'!J18 -> 3296 | H21: ='Raw FS'!K18 -> 3210 | I21: ='Raw FS'!L18 -> 3302 | J21: ='Raw FS'!M18 -> 3428 | K21: ='Raw FS'!N18 -> 3461
B22: ='Raw FS'!B19 -> Equipments | G22: ='Raw FS'!J19 -> 1371 | H22: ='Raw FS'!K19 -> 1427 | I22: ='Raw FS'!L19 -> 1482 | J22: ='Raw FS'!M19 -> 1528 | K22: ='Raw FS'!N19 -> 1628
B23: ='Raw FS'!B20 -> Computers | G23: ='Raw FS'!J20 -> 8650 | H23: ='Raw FS'!K20 -> 9936 | I23: ='Raw FS'!L20 -> 11898 | J23: ='Raw FS'!M20 -> 12353 | K23: ='Raw FS'!N20 -> 12925
B24: ='Raw FS'!B21 -> Furniture n fittings | G24: ='Raw FS'!J21 -> 2149 | H24: ='Raw FS'!K21 -> 2279 | I24: ='Raw FS'!L21 -> 2303 | J24: ='Raw FS'!M21 -> 2326 | K24: ='Raw FS'!N21 -> 2340
B25: ='Raw FS'!B22 -> Vehicles | G25: ='Raw FS'!J22 -> 74 | H25: ='Raw FS'!K22 -> 71 | I25: ='Raw FS'!L22 -> 60 | J25: ='Raw FS'!M22 -> 62 | K25: ='Raw FS'!N22 -> 72
B26: ='Raw FS'!B23 -> Intangible Assets | G26: ='Raw FS'!J23 -> 6372 | H26: ='Raw FS'!K23 -> 6495 | I26: ='Raw FS'!L23 -> 7594 | J26: ='Raw FS'!M23 -> 7653 | K26: ='Raw FS'!N23 -> 10626
B27: ='Raw FS'!B24 -> Other fixed assets | G27: ='Raw FS'!J24 -> 2730 | H27: ='Raw FS'!K24 -> 2766 | I27: ='Raw FS'!L24 -> 3281 | J27: ='Raw FS'!M24 -> 3294 | K27: ='Raw FS'!N24 -> 5184
B29: Gross Block | G29: =SUM(G19:G27) -> 43006 | H29: =SUM(H19:H27) -> 45010 | I29: =SUM(I19:I27) -> 48877 | J29: =SUM(J19:J27) -> 49196 | K29: =SUM(K19:K27) -> 54691
B30: Accumulated Depreciation | G30: =-'Raw FS'!J26 -> -17501 | H30: =-'Raw FS'!K26 -> -19210 | I30: =-'Raw FS'!L26 -> -19652 | J30: =-'Raw FS'!M26 -> -21574 | K30: =-'Raw FS'!N26 -> -23730
A31: # | B31: Net Non Current Assets | G31: =G29+G30 -> 25505 | H31: =H29+H30 -> 25800 | I31: =I29+I30 -> 29225 | J31: =J29+J30 -> 27622 | K31: =K29+K30 -> 30961
A33: # | B33: Invested Capital | G33: =G16+G31 -> 42266 | H33: =H16+H31 -> 42998 | I33: =I16+I31 -> 52155 | J33: =J16+J31 -> 57118 | K33: =K16+K31 -> 55620
B34: EBIT | G34: =(HistoricalFS!H27+HistoricalFS!H21) -> 24622 | H34: =(HistoricalFS!I27+HistoricalFS!I21) -> 28015 | I34: =(HistoricalFS!J27+HistoricalFS!J21) -> 30905 | J34: =(HistoricalFS!K27+HistoricalFS!K21) -> 31747 | K34: =(HistoricalFS!L27+HistoricalFS!L21) -> 34424
A36: # | B36: ROIC | G36: =G34/G33 -> 0.58254862 | H36: =H34/H33 -> 0.65154193 | I36: =I34/I33 -> 0.59256064 | J36: =J34/J33 -> 0.55581428 | K36: =K34/K33 -> 0.61891406
B39: Calculation of Reinvestment Rate | G39: =G2 -> 44256 | H39: =H2 -> 44621 | I39: =I2 -> 44986 | J39: =J2 -> 45352 | K39: =K2 -> 45717
B41: Net Capex | G41: =-SUM('Raw FS'!J50:J51) -> 2107 | H41: =-SUM('Raw FS'!K50:K51) -> 2161 | I41: =-SUM('Raw FS'!L50:L51) -> 2579 | J41: =-SUM('Raw FS'!M50:M51) -> 2201 | K41: =-SUM('Raw FS'!N50:N51) -> 2237
B42: Change in Working Capital | H42: =H16-G16 -> 437 | I42: =I16-H16 -> 5732 | J42: =J16-I16 -> 6566 | K42: =K16-J16 -> -4837
B44: EBIT | G44: =G34 -> 24622 | H44: =H34 -> 28015 | I44: =I34 -> 30905 | J44: =J34 -> 31747 | K44: =K34 -> 34424
B45: Marginal Tax Rate | G45: 0.25 | H45: 0.25 | I45: 0.25 | J45: 0.25 | K45: 0.25
B46: EBIT(1-T) | G46: =G44*(1-G45) -> 18466.5 | H46: =H44*(1-H45) -> 21011.25 | I46: =I44*(1-I45) -> 23178.75 | J46: =J44*(1-J45) -> 23810.25 | K46: =K44*(1-K45) -> 25818
B48: Reinvestment | H48: =SUM(H41:H42) -> 2598 | I48: =SUM(I41:I42) -> 8311 | J48: =SUM(J41:J42) -> 8767 | K48: =SUM(K41:K42) -> -2600
B50: Reinvestment Rate | H50: =H48/H46 -> 0.12364805 | I50: =I48/I46 -> 0.35856118 | J50: =J48/J46 -> 0.36820277 | K50: =K48/K46 -> -0.10070493
J52: 4 Year Average | K52: =AVERAGE(H50:K50) -> 0.18742677
J53: 4 Year Median | K53: =MEDIAN(H50:K50) -> 0.24110461
B55: Calculation of Reinvestment Rate | G55: =G39 -> 44256 | H55: =H39 -> 44621 | I55: =I39 -> 44986 | J55: =J39 -> 45352 | K55: =K39 -> 45717
B57: Reinvestment Rate | H57: =H50 -> 0.12364805 | I57: =I50 -> 0.35856118 | J57: =J50 -> 0.36820277 | K57: =K50 -> -0.10070493
...

Sheet DCF
B3: Calculation of PV of FCFF | E3: ='Intrinsic Growth'!K2 -> 45717 | F3: =E3+366 -> 46083 | G3: =F3+365 -> 46448 | H3: =G3+365 -> 46813 | I3: =H3+365 -> 47178 | J3: =I3+365 -> 47543
B5: EBIT | E5: ='Data Sheet'!K33-'Data Sheet'!K26 -> 37987 | F5: =E5*(1+$D$15) -> 43404.217 | G5: =F5*(1+$D$15) -> 49593.967 | H5: =G5*(1+$D$15) -> 56666.42 | I5: =H5*(1+$D$15) -> 64747.455 | J5: =I5*(1+$D$15) -> 73980.903
B6: Tax Rate | E6: 0.25 | F6: =E6 -> 0.25 | G6: =F6 -> 0.25 | H6: =G6 -> 0.25 | I6: =H6 -> 0.25 | J6: =I6 -> 0.25
B7: EBIT(1-T) | E7: =E5*(1-E6) -> 28490.25 | F7: =F5*(1-F6) -> 32553.163 | G7: =G5*(1-G6) -> 37195.475 | H7: =H5*(1-H6) -> 42499.815 | I7: =I5*(1-I6) -> 48560.591 | J7: =J5*(1-J6) -> 55485.678
B8: Less: Reinvestment Rate | E8: ='Intrinsic Growth'!K53 -> 0.24110461 | F8: =E8 -> 0.24110461 | G8: =F8 -> 0.24110461 | H8: =G8 -> 0.24110461 | I8: =H8 -> 0.24110461 | J8: =I8 -> 0.24110461
B9: Free Cash Flow to Firm (FCFF) | E9: =E7*(1-E8) -> 21621.119 | F9: =F7*(1-F8) -> 24704.445 | G9: =G7*(1-G8) -> 28227.475 | H9: =H7*(1-H8) -> 32252.914 | I9: =I7*(1-I8) -> 36852.409 | J9: =J7*(1-J8) -> 42107.825
B10: Mid Year Convention | F10: 0.5 | G10: =F10+1 -> 1.5 | H10: =G10+1 -> 2.5 | I10: =H10+1 -> 3.5 | J10: =I10+1 -> 4.5
B11: Discounting Factor | F11: =1/(1+$D$17)^F10 -> 0.92992875 | G11: =1/(1+$D$17)^G10 -> 0.80417214 | H11: =1/(1+$D$17)^H10 -> 0.69542191 | I11: =1/(1+$D$17)^I10 -> 0.60137825 | J11: =1/(1+$D$17)^J10 -> 0.52005235
B13: PV of FCFF | F13: =F9*F11 -> 22973.373 | G13: =G9*G11 -> 22699.749 | H13: =H9*H11 -> 22429.383 | I13: =I9*I11 -> 22162.237 | J13: =J9*J11 -> 21898.273
B15: Expected Growth | D15: ='Intrinsic Growth'!K63 -> 0.14260712
B16: Terminal Growth | D16: 0.055
B17: WACC | D17: =WACC!K43 -> 0.15638021
B20: Calculation of Terminal Value | F20: Sensitivity Analysis
F21: =D33 -> 358967.81 | G21: 0.13 | H21: 0.1564 | I21: 0.17 | J21: 0.19
B22: FCFF (n+1) | D22: =J9*(1+D15) -> 48112.7 | F22: 0.05 | G22: 424927.05 | H22: 347323.95 | I22: 320672.37 | J22: 290885.32
B23: WACC | D23: =D17 -> 0.15638021 | F23: 0.06 | G23: 469607.63 | H23: 371718.23 | I23: 339627.77 | J23: 304633.19
B24: Terminal Growth Rate | D24: =D16 -> 0.055 | F24: 0.074 | G24: 558968.78 | H24: 415817.42 | I24: 372799.71 | J24: 327862.35
F25: 0.08 | G25: 612585.48 | H25: 439664.63 | I25: 390175.49 | J25: 339627.77
B26: Terminal Value | D26: =D22/(D23-D24) -> 474576.83 | F26: 0.09 | G26: 737691.09 | H26: 488987.16 | I26: 424927.05 | J26: 362374.25
B29: Calculation of Equity Value per Share
B31: PV of FCFF | D31: =SUM(F13:J13) -> 112163.02
B32: PV of Terminal Value | D32: =D26*J11 -> 246804.8
B33: Value of Operating Assets | D33: =SUM(D31:D32) -> 358967.81
B35: Add : Cash | D35: ='Data Sheet'!K69 -> 24455
B36: Less : Debt | D36: =SUM('Raw FS'!N7) -> 8227
B37: Value of Equity | D37: =D33+D35-D36 -> 375195.81
B38: Number of Shares | D38: ='Data Sheet'!B6 -> 405.5231
B40: Equity Value Per Share | D40: =D37/D38 -> 925.21441
B42: Share Price | D42: 1229
B43: Discount/Premium | D43: =D42/D40 -> 1.3283407

Sheet Data Room>

Sheet Data Sheet
A1: COMPANY NAME | B1: INFOSYS LTD | E1: =IF(B2<>B3, "A NEW VERSION OF THE WORKSHEET IS AVAILABLE", "")
A2: LATEST VERSION | B2: 2.1 | E2: PLEASE DO NOT MAKE ANY CHANGES TO THIS SHEET
A3: CURRENT VERSION | B3: 2.1
A5: META
A6: Number of shares | B6: =IF(B9>0, B9/B8, 0) -> 405.5231
A7: Face Value | B7: 5
A8: Current Price | B8: 1248.3
A9: Market Capitalization | B9: 506214.48
A15: PROFIT & LOSS
A16: Report Date | B16: 42460 | C16: 42825 | D16: 43190 | E16: 43555 | F16: 43921 | G16: 44286 | H16: 44651 | I16: 45016 | J16: 45382 | K16: 45747
A17: Sales | B17: 62441 | C17: 68484 | D17: 70522 | E17: 82675 | F17: 90791 | G17: 100472 | H17: 121641 | I17: 146767 | J17: 153670 | K17: 162990
A18: Raw Material Cost
A19: Change in Inventory
A20: Power and Fuel | B20: 217 | C20: 228 | D20: 207 | E20: 221 | F20: 229 | G20: 143 | H20: 132 | I20: 176 | J20: 199 | K20: 222
A21: Other Mfr. Exp | B21: 5860 | C21: 6712 | D21: 7286 | E21: 9902 | F21: 11086 | G21: 12800 | H21: 20690 | I21: 26330 | J21: 27195 | K21: 30395
A22: Employee Cost | B22: 34415 | C22: 37669 | D22: 38902 | E22: 45323 | F22: 50895 | G22: 55547 | H22: 63997 | I22: 78374 | J22: 82636 | K22: 85968
A23: Selling and admin | B23: 4441 | C23: 4584 | D23: 4585 | E23: 5553 | F23: 5375 | G23: 3194 | H23: 4305 | I23: 5300 | J23: 5705 | K23: 6039
A24: Other Expenses | B24: 429 | C24: 687 | D24: 720 | E24: 1506 | F24: 939 | G24: 899 | H24: 1026 | I24: 1457 | J24: 1510 | K24: 1130
A25: Other Income | B25: 3120 | C25: 3050 | D25: 3311 | E25: 2882 | F25: 2803 | G25: 2201 | H25: 2295 | I25: 2701 | J25: 4711 | K25: 3600
A26: Depreciation | B26: 1459 | C26: 1703 | D26: 1863 | E26: 2011 | F26: 2893 | G26: 3267 | H26: 3476 | I26: 4225 | J26: 4678 | K26: 4812
A27: Interest | F27: 170 | G27: 195 | H27: 200 | I27: 284 | J27: 470 | K27: 416
A28: Profit before tax | B28: 18740 | C28: 19951 | D28: 20270 | E28: 21041 | F28: 22007 | G28: 26628 | H28: 30110 | I28: 33322 | J28: 35988 | K28: 37608
A29: Tax | B29: 5251 | C29: 5598 | D29: 4241 | E29: 5631 | F29: 5368 | G29: 7205 | H29: 7964 | I29: 9214 | J29: 9740 | K29: 10858
A30: Net profit | B30: 13489 | C30: 14353 | D30: 16029 | E30: 15404 | F30: 16594 | G30: 19351 | H30: 22110 | I30: 24095 | J30: 26233 | K30: 26713
A31: Dividend Amount | B31: 5548.4 | C31: 5891.6 | D31: 9465.6 | E31: 9222.5 | F31: 7427 | G31: 11469.6 | H31: 13007.6 | I31: 14069.2 | J31: 19053.2 | K31: 17827.8
A33: EBITDA | B33: =B30+B29+B27+B26 -> 20199 | C33: =C30+C29+C27+C26 -> 21654 | D33: =D30+D29+D27+D26 -> 22133 | E33: =E30+E29+E27+E26 -> 23046 | F33: =F30+F29+F27+F26 -> 25025 | G33: =G30+G29+G27+G26 -> 30018 | H33: =H30+H29+H27+H26 -> 33750 | I33: =I30+I29+I27+I26 -> 37818 | ... K33: =K30+K29+K27+K26 -> 42799
A40: Quarters
A41: Report Date | B41: 45199 | C41: 45291 | D41: 45382 | E41: 45473 | F41: 45565 | G41: 45657 | H41: 45747 | I41: 45838 | J41: 45930 | K41: 46022
A42: Sales | B42: 38994 | C42: 38821 | D42: 37923 | E42: 39315 | F42: 40986 | G42: 41764 | H42: 40925 | I42: 42279 | J42: 44490 | K42: 45479
A43: Expenses | B43: 29554 | C43: 29684 | D43: 29139 | E43: 29878 | F43: 31177 | G43: 31649 | H43: 31051 | I43: 32336 | J43: 33955 | K43: 34845
A44: Other Income | B44: 632 | C44: 789 | D44: 2729 | E44: 838 | F44: 712 | G44: 859 | H44: 1190 | I44: 1042 | J44: 982 | K44: -150
A45: Depreciation | B45: 1166 | C45: 1176 | D45: 1163 | E45: 1149 | F45: 1160 | G45: 1203 | H45: 1299 | I45: 1140 | J45: 1182 | K45: 1155
A46: Interest | B46: 138 | C46: 131 | D46: 110 | E46: 105 | F46: 108 | G46: 101 | H46: 102 | I46: 105 | J46: 106 | K46: 100
A47: Profit before tax | B47: 8768 | C47: 8619 | D47: 10240 | E47: 9021 | F47: 9253 | G47: 9670 | H47: 9663 | I47: 9740 | J47: 10229 | K47: 9229
A48: Tax | B48: 2553 | C48: 2506 | D48: 2265 | E48: 2647 | F48: 2737 | G48: 2848 | H48: 2625 | I48: 2816 | J48: 2854 | K48: 2563
A49: Net profit | B49: 6212 | C49: 6106 | D49: 7969 | E49: 6368 | F49: 6506 | G49: 6806 | H49: 7033 | I49: 6921 | J49: 7364 | K49: 6654
A50: Operating Profit | B50: 9440 | C50: 9137 | D50: 8784 | E50: 9437 | F50: 9809 | G50: 10115 | H50: 9874 | I50: 9943 | J50: 10535 | K50: 10634
A51: EBITDA | B51: =B49+B48+B46+B45 -> 10069 | C51: =C49+C48+C46+C45 -> 9919 | D51: =D49+D48+D46+D45 -> 11507 | E51: =E49+E48+E46+E45 -> 10269 | F51: =F49+F48+F46+F45 -> 10511 | G51: =G49+G48+G46+G45 -> 10958 | H51: =H49+H48+H46+H45 -> 11059 | I51: =I49+I48+I46+I45 -> 10982 | ... K51: =K49+K48+K46+K45 -> 10472
A55: BALANCE SHEET
A56: Report Date | B56: 42460 | C56: 42825 | D56: 43190 | E56: 43555 | F56: 43921 | G56: 44286 | H56: 44651 | I56: 45016 | J56: 45382 | K56: 45747
...

Sheet HistoricalFS
B2: ="Historical Financial Statement - "&'Data Sheet'!B1 -> Historical Financial Statement - INFOSYS LTD
B3: Years | C3: ='Data Sheet'!B16 -> 42460 | D3: ='Data Sheet'!C16 -> 42825 | E3: ='Data Sheet'!D16 -> 43190 | F3: ='Data Sheet'!E16 -> 43555 | G3: ='Data Sheet'!F16 -> 43921 | H3: ='Data Sheet'!G16 -> 44286 | I3: ='Data Sheet'!H16 -> 44651 | J3: ='Data Sheet'!I16 -> 45016 | ... L3: ='Data Sheet'!K16 -> 45747 | M3: LTM
A5: # | B5: Income Statement
B6: Sales | C6: ='Data Sheet'!B17 -> 62441 | D6: ='Data Sheet'!C17 -> 68484 | E6: ='Data Sheet'!D17 -> 70522 | F6: ='Data Sheet'!E17 -> 82675 | G6: ='Data Sheet'!F17 -> 90791 | H6: ='Data Sheet'!G17 -> 100472 | I6: ='Data Sheet'!H17 -> 121641 | J6: ='Data Sheet'!I17 -> 146767 | ... L6: ='Data Sheet'!K17 -> 162990 | M6: =IFERROR(SUM('Data Sheet'!H42:K42),0) -> 173173
B7: Sales Growth | C7: - | D7: =IFERROR(D6/C6-1,0) -> 0.09677936 | E7: =IFERROR(E6/D6-1,0) -> 0.029758776 | F7: =IFERROR(F6/E6-1,0) -> 0.1723292 | G7: =IFERROR(G6/F6-1,0) -> 0.098167523 | H7: =IFERROR(H6/G6-1,0) -> 0.10662951 | I7: =IFERROR(I6/H6-1,0) -> 0.21069552 | J7: =IFERROR(J6/I6-1,0) -> 0.20655864 | K7: =IFERROR(K6/J6-1,0) -> 0.047033734 | ... M7: =IFERROR(M6/L6-1,0) -> 0.062476226
B9: COGS | C9: =IFERROR(SUM('Data Sheet'!B18,'Data Sheet'!B20,'Data Sheet'!B21,'Data Sheet'!B22)-1*'Data Sheet'!B19,0) -> 40492 | D9: =IFERROR(SUM('Data Sheet'!C18,'Data Sheet'!C20,'Data Sheet'!C21,'Data Sheet'!C22)-1*'Data Sheet'!C19,0) -> 44609 | E9: =IFERROR(SUM('Data Sheet'!D18,'Data Sheet'!D20,'Data Sheet'!D21,'Data Sheet'!D22)-1*'Data Sheet'!D19,0) -> 46395 | F9: =IFERROR(SUM('Data Sheet'!E18,'Data Sheet'!E20,'Data Sheet'!E21,'Data Sheet'!E22)-1*'Data Sheet'!E19,0) -> 55446 | G9: =IFERROR(SUM('Data Sheet'!F18,'Data Sheet'!F20,'Data Sheet'!F21,'Data Sheet'!F22)-1*'Data Sheet'!F19,0) -> 62210 | H9: =IFERROR(SUM('Data Sheet'!G18,'Data Sheet'!G20,'Data Sheet'!G21,'Data Sheet'!G22)-1*'Data Sheet'!G19,0) -> 68490 | I9: =IFERROR(SUM('Data Sheet'!H18,'Data Sheet'!H20,'Data Sheet'!H21,'Data Sheet'!H22)-1*'Data Sheet'!H19,0) -> 84819 | J9: =IFERROR(SUM('Data Sheet'!I18,'Data Sheet'!I20,'Data Sheet'!I21,'Data Sheet'!I22)-1*'Data Sheet'!I19,0) -> 104880 | ... L9: =IFERROR(SUM('Data Sheet'!K18,'Data Sheet'!K20,'Data Sheet'!K21,'Data Sheet'!K22)-1*'Data Sheet'!K19,0) -> 116585 | M9: =IFERROR(SUM('Data Sheet'!H43:K43),0) -> 132187
B10: COSG % Sales | C10: =IFERROR(C9/C6,0) -> 0.64848417 | D10: =IFERROR(D9/D6,0) -> 0.65137842 | E10: =IFERROR(E9/E6,0) -> 0.65787981 | F10: =IFERROR(F9/F6,0) -> 0.67065014 | G10: =IFERROR(G9/G6,0) -> 0.68520007 | H10: =IFERROR(H9/H6,0) -> 0.68168246 | I10: =IFERROR(I9/I6,0) -> 0.69728957 | J10: =IFERROR(J9/J6,0) -> 0.71460206 | ... M10: =IFERROR(M9/M6,0) -> 0.76332338
B12: Gross Profit | C12: =C6-C9 -> 21949 | D12: =D6-D9 -> 23875 | E12: =E6-E9 -> 24127 | F12: =F6-F9 -> 27229 | G12: =G6-G9 -> 28581 | H12: =H6-H9 -> 31982 | I12: =I6-I9 -> 36822 | J12: =J6-J9 -> 41887 | ... M12: =M6-M9 -> 40986
B13: Gross Margins | C13: =IFERROR(C12/C6,0) -> 0.35151583 | D13: =IFERROR(D12/D6,0) -> 0.34862158 | E13: =IFERROR(E12/E6,0) -> 0.34212019 | F13: =IFERROR(F12/F6,0) -> 0.32934986 | G13: =IFERROR(G12/G6,0) -> 0.31479993 | H13: =IFERROR(H12/H6,0) -> 0.31831754 | I13: =IFERROR(I12/I6,0) -> 0.30271043 | J13: =IFERROR(J12/J6,0) -> 0.28539794 | ... M13: =IFERROR(M12/M6,0) -> 0.23667662
B15: Selling & General Expenses | C15: =IFERROR(SUM('Data Sheet'!B23:B24),0) -> 4870 | D15: =IFERROR(SUM('Data Sheet'!C23:C24),0) -> 5271 | E15: =IFERROR(SUM('Data Sheet'!D23:D24),0) -> 5305 | F15: =IFERROR(SUM('Data Sheet'!E23:E24),0) -> 7059 | G15: =IFERROR(SUM('Data Sheet'!F23:F24),0) -> 6314 | H15: =IFERROR(SUM('Data Sheet'!G23:G24),0) -> 4093 | I15: =IFERROR(SUM('Data Sheet'!H23:H24),0) -> 5331 | J15: =IFERROR(SUM('Data Sheet'!I23:I24),0) -> 6757 | ... M15: =IFERROR(SUM('Data Sheet'!L23:L24),0) -> 0
B16: S&G Exp % Sales | C16: =IFERROR(C15/C6,0) -> 0.077993626 | D16: =IFERROR(D15/D6,0) -> 0.076966883 | E16: =IFERROR(E15/E6,0) -> 0.075224753 | F16: =IFERROR(F15/F6,0) -> 0.085382522 | G16: =IFERROR(G15/G6,0) -> 0.069544338 | H16: =IFERROR(H15/H6,0) -> 0.040737718 | I16: =IFERROR(I15/I6,0) -> 0.043825684 | J16: =IFERROR(J15/J6,0) -> 0.04603896 | ... M16: =IFERROR(M15/M6,0) -> 0
B18: EBITDA | C18: =C12-C15 -> 17079 | D18: =D12-D15 -> 18604 | E18: =E12-E15 -> 18822 | F18: =F12-F15 -> 20170 | G18: =G12-G15 -> 22267 | H18: =H12-H15 -> 27889 | I18: =I12-I15 -> 31491 | J18: =J12-J15 -> 35130 | ... L18: =L12-L15 -> 39236 | M18: =IFERROR(SUM('Data Sheet'!H51:K51),0) -> 44019
B19: EBITDA Margins | C19: =IFERROR(C18/C6,0) -> 0.2735222 | D19: =IFERROR(D18/D6,0) -> 0.27165469 | E19: =IFERROR(E18/E6,0) -> 0.26689544 | F19: =IFERROR(F18/F6,0) -> 0.24396734 | G19: =IFERROR(G18/G6,0) -> 0.24525559 | H19: =IFERROR(H18/H6,0) -> 0.27757982 | I19: =IFERROR(I18/I6,0) -> 0.25888475 | J19: =IFERROR(J18/J6,0) -> 0.23935898 | ... M19: =IFERROR(M18/M6,0) -> 0.2541909
B21: Interest | C21: =IFERROR('Data Sheet'!B27,0) -> 0 | D21: =IFERROR('Data Sheet'!C27,0) -> 0 | E21: =IFERROR('Data Sheet'!D27,0) -> 0 | F21: =IFERROR('Data Sheet'!E27,0) -> 0 | G21: =IFERROR('Data Sheet'!F27,0) -> 170 | H21: =IFERROR('Data Sheet'!G27,0) -> 195 | I21: =IFERROR('Data Sheet'!H27,0) -> 200 | J21: =IFERROR('Data Sheet'!I27,0) -> 284 | ... L21: =IFERROR('Data Sheet'!K27,0) -> 416 | M21: =IFERROR(SUM('Data Sheet'!H46:K46),0) -> 413
B22: Interest % Sales | C22: =IFERROR(C21/C6,0) -> 0 | D22: =IFERROR(D21/D6,0) -> 0 | E22: =IFERROR(E21/E6,0) -> 0 | F22: =IFERROR(F21/F6,0) -> 0 | G22: =IFERROR(G21/G6,0) -> 0.0018724323 | H22: =IFERROR(H21/H6,0) -> 0.0019408392 | I22: =IFERROR(I21/I6,0) -> 0.0016441825 | J22: =IFERROR(J21/J6,0) -> 0.0019350399 | ... M22: =IFERROR(M21/M6,0) -> 0.0023848983
B24: Depreciation | C24: =IFERROR('Data Sheet'!B26,0) -> 1459 | D24: =IFERROR('Data Sheet'!C26,0) -> 1703 | E24: =IFERROR('Data Sheet'!D26,0) -> 1863 | F24: =IFERROR('Data Sheet'!E26,0) -> 2011 | G24: =IFERROR('Data Sheet'!F26,0) -> 2893 | H24: =IFERROR('Data Sheet'!G26,0) -> 3267 | I24: =IFERROR('Data Sheet'!H26,0) -> 3476 | J24: =IFERROR('Data Sheet'!I26,0) -> 4225 | ... L24: =IFERROR('Data Sheet'!K26,0) -> 4812 | M24: =IFERROR(SUM('Data Sheet'!H45:K45),0) -> 4776
B25: Deprecaiton % Sales | C25: =IFERROR(C24/C6,0) -> 0.023366058 | D25: =IFERROR(D24/D6,0) -> 0.024867122 | E25: =IFERROR(E24/E6,0) -> 0.026417288 | F25: =IFERROR(F24/F6,0) -> 0.024324161 | G25: =IFERROR(G24/G6,0) -> 0.031864392 | H25: =IFERROR(H24/H6,0) -> 0.032516522 | I25: =IFERROR(I24/I6,0) -> 0.028575891 | J25: =IFERROR(J24/J6,0) -> 0.028787125 | ... M25: =IFERROR(M24/M6,0) -> 0.027579357
B27: Earnings Before Tax | C27: =IFERROR(C18-SUM(C21+C24),0) -> 15620 | D27: =IFERROR(D18-SUM(D21+D24),0) -> 16901 | E27: =IFERROR(E18-SUM(E21+E24),0) -> 16959 | F27: =IFERROR(F18-SUM(F21+F24),0) -> 18159 | G27: =IFERROR(G18-SUM(G21+G24),0) -> 19204 | H27: =IFERROR(H18-SUM(H21+H24),0) -> 24427 | I27: =IFERROR(I18-SUM(I21+I24),0) -> 27815 | J27: =IFERROR(J18-SUM(J21+J24),0) -> 30621 | ... M27: =IFERROR(M18-SUM(M21+M24),0) -> 38830
B28: EBT % Sales | C28: =IFERROR(C27/C6,0) -> 0.25015615 | D28: =IFERROR(D27/D6,0) -> 0.24678757 | E28: =IFERROR(E27/E6,0) -> 0.24047815 | F28: =IFERROR(F27/F6,0) -> 0.21964318 | G28: =IFERROR(G27/G6,0) -> 0.21151876 | H28: =IFERROR(H27/H6,0) -> 0.24312246 | I28: =IFERROR(I27/I6,0) -> 0.22866468 | J28: =IFERROR(J27/J6,0) -> 0.20863682 | ... M28: =IFERROR(M27/M6,0) -> 0.22422664
B30: Tax | C30: =IFERROR('Data Sheet'!B29,0) -> 5251 | D30: =IFERROR('Data Sheet'!C29,0) -> 5598 | E30: =IFERROR('Data Sheet'!D29,0) -> 4241 | F30: =IFERROR('Data Sheet'!E29,0) -> 5631 | G30: =IFERROR('Data Sheet'!F29,0) -> 5368 | H30: =IFERROR('Data Sheet'!G29,0) -> 7205 | I30: =IFERROR('Data Sheet'!H29,0) -> 7964 | J30: =IFERROR('Data Sheet'!I29,0) -> 9214 | ... L30: =IFERROR('Data Sheet'!K29,0) -> 10858 | M30: =IFERROR(SUM('Data Sheet'!H48:K48),0) -> 10858
B31: Effective Tax Rate | C31: =IFERROR(C30/C27,0) -> 0.33617157 | D31: =IFERROR(D30/D27,0) -> 0.331223 | E31: =IFERROR(E30/E27,0) -> 0.25007371 | F31: =IFERROR(F30/F27,0) -> 0.31009417 | G31: =IFERROR(G30/G27,0) -> 0.2795251 | H31: =IFERROR(H30/H27,0) -> 0.29496049 | I31: =IFERROR(I30/I27,0) -> 0.28632033 | J31: =IFERROR(J30/J27,0) -> 0.30090461 | ... M31: =IFERROR(M30/M27,0) -> 0.27962915
B33: Net Profit | C33: =IFERROR(C27-C30,0) -> 10369 | D33: =IFERROR(D27-D30,0) -> 11303 | E33: =IFERROR(E27-E30,0) -> 12718 | F33: =IFERROR(F27-F30,0) -> 12528 | G33: =IFERROR(G27-G30,0) -> 13836 | H33: =IFERROR(H27-H30,0) -> 17222 | I33: =IFERROR(I27-I30,0) -> 19851 | J33: =IFERROR(J27-J30,0) -> 21407 | ... M33: =IFERROR(M27-M30,0) -> 27972
B34: Net Margins | C34: =IFERROR(C33/C6,0) -> 0.16606076 | D34: =IFERROR(D33/D6,0) -> 0.16504585 | E34: =IFERROR(E33/E6,0) -> 0.18034089 | F34: =IFERROR(F33/F6,0) -> 0.15153311 | G34: =IFERROR(G33/G6,0) -> 0.15239396 | H34: =IFERROR(H33/H6,0) -> 0.17141094 | I34: =IFERROR(I33/I6,0) -> 0.16319333 | J34: =IFERROR(J33/J6,0) -> 0.14585704 | ... M34: =IFERROR(M33/M6,0) -> 0.16152633
B36: No of Equity Shares | C36: =IFERROR('Data Sheet'!B93,0) -> 459.39 | D36: =IFERROR('Data Sheet'!C93,0) -> 459.39 | E36: =IFERROR('Data Sheet'!D93,0) -> 436.82 | F36: =IFERROR('Data Sheet'!E93,0) -> 436.89 | G36: =IFERROR('Data Sheet'!F93,0) -> 425.9 | H36: =IFERROR('Data Sheet'!G93,0) -> 426.07 | I36: =IFERROR('Data Sheet'!H93,0) -> 420.67 | J36: =IFERROR('Data Sheet'!I93,0) -> 414.86 | ... M36: =IFERROR('Data Sheet'!L93,0) -> 0
B38: Earnings per Share | C38: =IFERROR(C33/C36,0) -> 22.571236 | D38: =IFERROR(D33/D36,0) -> 24.604367 | E38: =IFERROR(E33/E36,0) -> 29.114967 | F38: =IFERROR(F33/F36,0) -> 28.67541 | G38: =IFERROR(G33/G36,0) -> 32.486499 | H38: =IFERROR(H33/H36,0) -> 40.420588 | I38: =IFERROR(I33/I36,0) -> 47.189008 | J38: =IFERROR(J33/J36,0) -> 51.60054 | ... M38: =IFERROR(M33/M36,0) -> 0
B39: EPS Growth % | D39: =IFERROR(D38/C38-1,0) -> 0.090076189 | E39: =E38/D38-1 -> 0.18332521 | F39: =F38/E38-1 -> -0.015097286 | G39: =G38/F38-1 -> 0.13290442 | H39: =H38/G38-1 -> 0.24422727 | I39: =I38/H38-1 -> 0.16744981 | J39: =J38/I38-1 -> 0.093486431 | K39: =K38/J38-1 -> 0.0055153183 | L39: =L38/K38-1 -> 0.074273236 | M39: =M38/L38-1 -> -1
B41: Dividend per Share | C41: =IFERROR('Data Sheet'!B31/HistoricalFS!C36,0) -> 12.077755 | D41: =IFERROR('Data Sheet'!C31/HistoricalFS!D36,0) -> 12.824833 | E41: =IFERROR('Data Sheet'!D31/HistoricalFS!E36,0) -> 21.669337 | F41: =IFERROR('Data Sheet'!E31/HistoricalFS!F36,0) -> 21.109433 | G41: =IFERROR('Data Sheet'!F31/HistoricalFS!G36,0) -> 17.438366 | H41: =IFERROR('Data Sheet'!G31/HistoricalFS!H36,0) -> 26.91952 | I41: =IFERROR('Data Sheet'!H31/HistoricalFS!I36,0) -> 30.92115 | J41: =IFERROR('Data Sheet'!I31/HistoricalFS!J36,0) -> 33.913127 | ... M41: =IFERROR('Data Sheet'!L31/HistoricalFS!M36,0) -> 0
B42: Dividend Payout Ratio | C42: =IFERROR(C41/C38,0) -> 0.53509499 | D42: =IFERROR(D41/D38,0) -> 0.52124215 | E42: =IFERROR(E41/E38,0) -> 0.74426797 | F42: =IFERROR(F41/F38,0) -> 0.73615102 | G42: =IFERROR(G41/G38,0) -> 0.53678809 | H42: =IFERROR(H41/H38,0) -> 0.66598537 | I42: =IFERROR(I41/I38,0) -> 0.6552617 | J42: =IFERROR(J41/J38,0) -> 0.65722427 | ... M42: =IFERROR(M41/M38,0) -> 0
B44: Retained Earnings | C44: =IFERROR(IF(C38>C41,1-C42,0),0) -> 0.46490501 | D44: =IFERROR(IF(D38>D41,1-D42,0),0) -> 0.47875785 | E44: =IFERROR(IF(E38>E41,1-E42,0),0) -> 0.25573203 | F44: =IFERROR(IF(F38>F41,1-F42,0),0) -> 0.26384898 | G44: =IFERROR(IF(G38>G41,1-G42,0),0) -> 0.46321191 | H44: =IFERROR(IF(H38>H41,1-H42,0),0) -> 0.33401463 | I44: =IFERROR(IF(I38>I41,1-I42,0),0) -> 0.3447383 | J44: =IFERROR(IF(J38>J41,1-J42,0),0) -> 0.34277573 | ... M44: =IFERROR(IF(M38>M41,1-M42,0),0) -> 0
A46: # | B46: Balance Sheet
B47: Equity Share Capital | C47: =IFERROR('Data Sheet'!B57,0) -> 1144 | D47: =IFERROR('Data Sheet'!C57,0) -> 1144 | E47: =IFERROR('Data Sheet'!D57,0) -> 1088 | F47: =IFERROR('Data Sheet'!E57,0) -> 2170 | G47: =IFERROR('Data Sheet'!F57,0) -> 2122 | H47: =IFERROR('Data Sheet'!G57,0) -> 2124 | I47: =IFERROR('Data Sheet'!H57,0) -> 2098 | J47: =IFERROR('Data Sheet'!I57,0) -> 2069 | ... L47: =IFERROR('Data Sheet'!K57,0) -> 2073
B48: Reserves | C48: =IFERROR('Data Sheet'!B58,0) -> 60600 | D48: =IFERROR('Data Sheet'!C58,0) -> 67838 | E48: =IFERROR('Data Sheet'!D58,0) -> 63835 | F48: =IFERROR('Data Sheet'!E58,0) -> 62778 | G48: =IFERROR('Data Sheet'!F58,0) -> 63328 | H48: =IFERROR('Data Sheet'!G58,0) -> 74227 | I48: =IFERROR('Data Sheet'!H58,0) -> 73252 | J48: =IFERROR('Data Sheet'!I58,0) -> 73338 | ... L48: =IFERROR('Data Sheet'!K58,0) -> 93745
B49: Borrowings | C49: =IFERROR('Data Sheet'!B59,0) -> 0 | D49: =IFERROR('Data Sheet'!C59,0) -> 0 | E49: =IFERROR('Data Sheet'!D59,0) -> 0 | F49: =IFERROR('Data Sheet'!E59,0) -> 0 | G49: =IFERROR('Data Sheet'!F59,0) -> 4633 | H49: =IFERROR('Data Sheet'!G59,0) -> 5325 | I49: =IFERROR('Data Sheet'!H59,0) -> 5474 | J49: =IFERROR('Data Sheet'!I59,0) -> 8299 | ... L49: =IFERROR('Data Sheet'!K59,0) -> 8227
B50: Other Liabilities | C50: =IFERROR('Data Sheet'!B60,0) -> 13354 | D50: =IFERROR('Data Sheet'!C60,0) -> 14166 | E50: =IFERROR('Data Sheet'!D60,0) -> 14426 | F50: =IFERROR('Data Sheet'!E60,0) -> 19118 | G50: =IFERROR('Data Sheet'!F60,0) -> 21717 | H50: =IFERROR('Data Sheet'!G60,0) -> 25835 | I50: =IFERROR('Data Sheet'!H60,0) -> 35905 | J50: =IFERROR('Data Sheet'!I60,0) -> 40890 | ... L50: =IFERROR('Data Sheet'!K60,0) -> 43750
B51: Total Laibilities | C51: =IFERROR('Data Sheet'!B61,0) -> 75098 | D51: =IFERROR('Data Sheet'!C61,0) -> 83148 | E51: =IFERROR('Data Sheet'!D61,0) -> 79349 | F51: =IFERROR('Data Sheet'!E61,0) -> 84066 | G51: =IFERROR('Data Sheet'!F61,0) -> 91800 | H51: =IFERROR('Data Sheet'!G61,0) -> 107511 | I51: =IFERROR('Data Sheet'!H61,0) -> 116729 | J51: =IFERROR('Data Sheet'!I61,0) -> 124596 | ... L51: =IFERROR('Data Sheet'!K61,0) -> 147795
B53: Fixed Asset Net Block | C53: =IFERROR('Data Sheet'!B62,0) -> 13386 | D53: =IFERROR('Data Sheet'!C62,0) -> 14179 | E53: =IFERROR('Data Sheet'!D62,0) -> 12574 | F53: =IFERROR('Data Sheet'!E62,0) -> 15710 | G53: =IFERROR('Data Sheet'!F62,0) -> 23789 | H53: =IFERROR('Data Sheet'!G62,0) -> 25505 | I53: =IFERROR('Data Sheet'!H62,0) -> 25800 | J53: =IFERROR('Data Sheet'!I62,0) -> 29225 | ... L53: =IFERROR('Data Sheet'!K62,0) -> 30961
B54: Capital Work in Progress | C54: =IFERROR('Data Sheet'!B63,0) -> 960 | D54: =IFERROR('Data Sheet'!C63,0) -> 1365 | E54: =IFERROR('Data Sheet'!D63,0) -> 1606 | F54: =IFERROR('Data Sheet'!E63,0) -> 1388 | G54: =IFERROR('Data Sheet'!F63,0) -> 954 | H54: =IFERROR('Data Sheet'!G63,0) -> 922 | I54: =IFERROR('Data Sheet'!H63,0) -> 416 | J54: =IFERROR('Data Sheet'!I63,0) -> 288 | ... L54: =IFERROR('Data Sheet'!K63,0) -> 814
B55: Investments | C55: =IFERROR('Data Sheet'!B64,0) -> 1892 | D55: =IFERROR('Data Sheet'!C64,0) -> 16423 | E55: =IFERROR('Data Sheet'!D64,0) -> 12163 | F55: =IFERROR('Data Sheet'!E64,0) -> 11261 | G55: =IFERROR('Data Sheet'!F64,0) -> 8792 | H55: =IFERROR('Data Sheet'!G64,0) -> 14205 | I55: =IFERROR('Data Sheet'!H64,0) -> 20324 | J55: =IFERROR('Data Sheet'!I64,0) -> 19478 | ... L55: =IFERROR('Data Sheet'!K64,0) -> 23541
B56: Other Assets | C56: =IFERROR('Data Sheet'!B65-(SUM('Data Sheet'!B67:B69)),0) -> 14833 | D56: =IFERROR('Data Sheet'!C65-(SUM('Data Sheet'!C67:C69)),0) -> 16234 | E56: =IFERROR('Data Sheet'!D65-(SUM('Data Sheet'!D67:D69)),0) -> 20046 | F56: =IFERROR('Data Sheet'!E65-(SUM('Data Sheet'!E67:E69)),0) -> 21312 | G56: =IFERROR('Data Sheet'!F65-(SUM('Data Sheet'!F67:F69)),0) -> 21129 | H56: =IFERROR('Data Sheet'!G65-(SUM('Data Sheet'!G67:G69)),0) -> 22871 | I56: =IFERROR('Data Sheet'!H65-(SUM('Data Sheet'!H67:H69)),0) -> 30019 | J56: =IFERROR('Data Sheet'!I65-(SUM('Data Sheet'!I67:I69)),0) -> 38008 | ... L56: =IFERROR('Data Sheet'!K65-(SUM('Data Sheet'!K67:K69)),0) -> 36866
B57: Total Non Current Assets | C57: =IFERROR(SUM(C53:C56),0) -> 31071 | D57: =IFERROR(SUM(D53:D56),0) -> 48201 | E57: =IFERROR(SUM(E53:E56),0) -> 46389 | F57: =IFERROR(SUM(F53:F56),0) -> 49671 | G57: =IFERROR(SUM(G53:G56),0) -> 54664 | H57: =IFERROR(SUM(H53:H56),0) -> 63503 | I57: =IFERROR(SUM(I53:I56),0) -> 76559 | J57: =IFERROR(SUM(J53:J56),0) -> 86999 | ... L57: =IFERROR(SUM(L53:L56),0) -> 92182
...

Sheet Raw FS
C2: 41699 | D2: 42064 | E2: 42430 | F2: 42795 | G2: 43160 | H2: 43525 | I2: 43891 | J2: 44256 | K2: 44621 | L2: 44986 | M2: 45352 | N2: 45717
B4: Equity Capital | C4: 286 | D4: 572 | E4: 1144 | F4: 1144 | G4: 1088 | H4: 2170 | I4: 2122 | J4: 2124 | K4: 2098 | L4: 2069 | M4: 2071 | N4: 2073
B5: Reserves | C5: 44244 | D5: 50164 | E5: 60600 | F5: 67838 | G5: 63835 | H5: 62778 | I5: 63328 | J5: 74227 | K5: 73252 | L5: 73338 | M5: 86045 | N5: 93745
B6: Borrowings -
B7: Lease Liabilities | C7: 0 | D7: 0 | E7: 0 | F7: 0 | G7: 0 | H7: 0 | I7: 4633 | J7: 5325 | K7: 5474 | L7: 8299 | M7: 8359 | N7: 8227
B8: Other Liabilities -
B9: Non controlling int | C9: 0 | D9: 0 | E9: 0 | F9: 0 | G9: 1 | H9: 58 | I9: 394 | J9: 431 | K9: 386 | L9: 388 | M9: 345 | N9: 385
B10: Trade Payables | C10: 173 | D10: 140 | E10: 386 | F10: 367 | G10: 694 | H10: 1655 | I10: 2852 | J10: 2645 | K10: 4134 | L10: 3865 | M10: 3956 | N10: 4164
B11: Advance from Customers | C11: 40 | D11: 27 | E11: 28 | F11: 0 | G11: 0 | H11: 0 | I11: 0 | J11: 0 | K11: 0 | L11: 0 | M11: 0 | N11: 0
B12: Other liability items | C12: 12223 | D12: 15386 | E12: 12940 | F12: 13799 | G12: 13731 | H12: 17405 | I12: 18471 | J12: 22759 | K12: 31385 | L12: 36637 | M12: 36584 | N12: 39201
B13: Total Liabilities | C13: 56966 | D13: 66289 | E13: 75098 | F13: 83148 | G13: 79349 | H13: 84066 | I13: 91800 | J13: 107511 | K13: 116729 | L13: 124596 | M13: 137360 | N13: 147795
B15: Fixed Assets -
B16: Land | C16: 1142 | D16: 1564 | E16: 1622 | F16: 1095 | G16: 1229 | H16: 1307 | I16: 1950 | J16: 2036 | K16: 2065 | L16: 2054 | M16: 2037 | N16: 2079
B17: Building | C17: 5238 | D17: 6102 | E17: 6325 | F17: 8419 | G17: 9334 | H17: 10270 | I17: 15104 | J17: 16328 | K17: 16761 | L17: 16903 | M17: 16515 | N17: 16376
B18: Plant Machinery | C18: 1150 | D18: 1427 | E18: 1759 | F18: 2048 | G18: 2306 | H18: 2709 | I18: 3185 | J18: 3296 | K18: 3210 | L18: 3302 | M18: 3428 | N18: 3461
B19: Equipments | C19: 551 | D19: 676 | E19: 839 | F19: 922 | G19: 1002 | H19: 1101 | I19: 1265 | J19: 1371 | K19: 1427 | L19: 1482 | M19: 1528 | N19: 1628
B20: Computers | C20: 2659 | D20: 3347 | E20: 4486 | F20: 4945 | G20: 4903 | H20: 6287 | I20: 7423 | J20: 8650 | K20: 9936 | L20: 11898 | M20: 12353 | N20: 12925
B21: Furniture n fittings | C21: 805 | D21: 958 | E21: 1444 | F21: 1277 | G21: 1393 | H21: 1620 | I21: 2073 | J21: 2149 | K21: 2279 | L21: 2303 | M21: 2326 | N21: 2340
B22: Vehicles | C22: 35 | D22: 34 | E22: 29 | F22: 31 | G22: 31 | H22: 38 | I22: 69 | J22: 74 | K22: 71 | L22: 60 | M22: 62 | N22: 72
B23: Intangible Assets | C23: 2244 | D23: 3637 | E23: 3858 | F23: 3743 | G23: 2237 | H23: 3640 | I23: 5527 | J23: 6372 | K23: 6495 | L23: 7594 | M23: 7653 | N23: 10626
B24: Other fixed assets | C24: 126 | D24: 71 | E24: 931 | F24: 899 | G24: 545 | H24: 1093 | I24: 2289 | J24: 2730 | K24: 2766 | L24: 3281 | M24: 3294 | N24: 5184
B25: Gross Block | C25: 13950 | D25: 17816 | E25: 21293 | F25: 23379 | G25: 22980 | H25: 28065 | I25: 38885 | J25: 43006 | K25: 45010 | L25: 48877 | M25: 49196 | N25: 54691
B26: Accumulated Depreciation | C26: 5572 | D26: 6470 | E26: 7907 | F26: 9200 | G26: 10406 | H26: 12355 | I26: 15096 | J26: 17501 | K26: 19210 | L26: 19652 | M26: 21574 | N26: 23730
B27: Net Block | C27: =C25-C26 -> 8378 | D27: =D25-D26 -> 11346 | E27: =E25-E26 -> 13386 | F27: =F25-F26 -> 14179 | G27: =G25-G26 -> 12574 | H27: =H25-H26 -> 15710 | I27: =I25-I26 -> 23789 | J27: =J25-J26 -> 25505 | ... N27: =N25-N26 -> 30961
B29: CWIP | C29: 961 | D29: 776 | E29: 960 | F29: 1365 | G29: 1606 | H29: 1388 | I29: 954 | J29: 922 | K29: 416 | L29: 288 | M29: 293 | N29: 814
B30: Investments | C30: 4331 | D30: 2270 | E30: 1892 | F30: 16423 | G30: 12163 | H30: 11261 | I30: 8792 | J30: 14205 | K30: 20324 | L30: 19478 | M30: 24623 | N30: 23541
B32: Other Assets -
B33: Trade receivables | C33: 8351 | D33: 9713 | E33: 11330 | F33: 12322 | G33: 13142 | H33: 14827 | I33: 18487 | J33: 19294 | K33: 22698 | L33: 25424 | M33: 30193 | N33: 31158
B34: Cash Equivalents | C34: 25950 | D34: 30367 | E34: 32697 | F34: 22625 | G34: 19818 | H34: 19568 | I34: 18649 | J34: 24714 | K34: 17472 | L34: 12173 | M34: 14786 | N34: 24455
B35: Loans n Advances | C35: 1484 | D35: 399 | E35: 614 | F35: 844 | G35: 830 | H35: 1524 | I35: 1359 | J35: 1460 | K35: 2491 | L35: 3242 | M35: 10330 | N35: 6717
B36: Other asset items | C36: 7511 | D36: 11418 | E36: 14219 | F36: 15390 | G36: 19216 | H36: 19788 | I36: 19770 | J36: 21411 | K36: 27528 | L36: 34766 | M36: 29513 | N36: 30149
B37: Total Assets | C37: 56966 | D37: 66289 | E37: 75098 | F37: 83148 | G37: 79349 | H37: 84066 | I37: 91800 | J37: 107511 | K37: 116729 | L37: 124596 | M37: 137360 | N37: 147795
C40: 41699 | D40: 42064 | E40: 42430 | F40: 42795 | G40: 43160 | H40: 43525 | I40: 43891 | J40: 44256 | K40: 44621 | L40: 44986 | M40: 45352 | N40: 45717
B41: Cash from Operating Activity - | C41: =C42+C47+C48 -> 9825 | D41: =D42+D47+D48 -> 8353 | E41: =E42+E47+E48 -> 10028 | F41: =F42+F47+F48 -> 11531 | G41: =G42+G47+G48 -> 13218 | H41: =H42+H47+H48 -> 14841 | I41: =I42+I47+I48 -> 17003 | J41: =J42+J47+J48 -> 23224 | ... N41: =N42+N47+N48 -> 35694
B42: Profit from operations | C42: 14172 | D42: 15946 | E42: 17839 | F42: 19340 | G42: 19963 | H42: 22126 | I42: 23920 | J42: 28845 | K42: 32921 | L42: 37605 | M42: 39523 | N42: 41591
B43: Receivables | C43: -1406 | D43: -1475 | E43: -1654 | F43: -1743 | G43: -1523 | H43: -2881 | I43: -3861 | J43: -1835 | K43: -7937 | L43: -7076 | M43: -2667 | N43: -1769
B44: Payables | C44: 0 | D44: 0 | E44: 242 | F44: -19 | G44: 328 | H44: 916 | I44: -373 | J44: -245 | K44: 1489 | L44: -279 | M44: 91 | N44: 176
B45: Loans Advances | C45: -1060 | D45: -221 | E45: -1134 | F45: 0 | G45: 0 | H45: 0 | I45: 0 | J45: -534 | K45: -1914 | L45: -3108 | M45: -1172 | N45: -1024
B46: Other WC items | C46: 1993 | D46: 854 | E46: 600 | F46: -394 | G46: 1279 | H46: 1512 | I46: 1867 | J46: 3382 | K46: 6938 | L46: 4119 | M46: -1334 | N46: 2322
B47: Working capital changes | C47: -473 | D47: -842 | E47: -1946 | F47: -2156 | G47: 84 | H47: -453 | I47: -2367 | J47: 768 | K47: -1424 | L47: -6344 | M47: -5082 | N47: -295
...

Sheet Cash Flow Data
C2: 41699 | D2: 42064 | E2: 42430 | F2: 42795 | G2: 43160 | H2: 43525 | I2: 43891 | J2: 44256 | K2: 44621 | L2: 44986 | M2: 45352 | N2: 45717
B3: Cash from Operating Activity - | C3: =C4+C9+C10 -> 9825 | D3: =D4+D9+D10 -> 8353 | E3: =E4+E9+E10 -> 10028 | F3: =F4+F9+F10 -> 11531 | G3: =G4+G9+G10 -> 13218 | H3: =H4+H9+H10 -> 14841 | I3: =I4+I9+I10 -> 17003 | J3: =J4+J9+J10 -> 23224 | ... N3: =N4+N9+N10 -> 35694
B4: Profit from operations | C4: 14172 | D4: 15946 | E4: 17839 | F4: 19340 | G4: 19963 | H4: 22126 | I4: 23920 | J4: 28845 | K4: 32921 | L4: 37605 | M4: 39523 | N4: 41591
B5: Receivables | C5: -1406 | D5: -1475 | E5: -1654 | F5: -1743 | G5: -1523 | H5: -2881 | I5: -3861 | J5: -1835 | K5: -7937 | L5: -7076 | M5: -2667 | N5: -1769
B6: Payables | C6: 0 | D6: 0 | E6: 242 | F6: -19 | G6: 328 | H6: 916 | I6: -373 | J6: -245 | K6: 1489 | L6: -279 | M6: 91 | N6: 176
B7: Loans Advances | C7: -1060 | D7: -221 | E7: -1134 | F7: 0 | G7: 0 | H7: 0 | I7: 0 | J7: -534 | K7: -1914 | L7: -3108 | M7: -1172 | N7: -1024
B8: Other WC items | C8: 1993 | D8: 854 | E8: 600 | F8: -394 | G8: 1279 | H8: 1512 | I8: 1867 | J8: 3382 | K8: 6938 | L8: 4119 | M8: -1334 | N8: 2322
B9: Working capital changes | C9: -473 | D9: -842 | E9: -1946 | F9: -2156 | G9: 84 | H9: -453 | I9: -2367 | J9: 768 | K9: -1424 | L9: -6344 | M9: -5082 | N9: -295
B10: Direct taxes | C10: -3874 | D10: -6751 | E10: -5865 | F10: -5653 | G10: -6829 | H10: -6832 | I10: -4550 | J10: -6389 | K10: -7612 | L10: -8794 | M10: -9231 | N10: -5602
B11: Cash from Investing Activity - | C11: -2563 | D11: 999 | E11: -885 | F11: -14664 | G11: 4533 | H11: -632 | I11: -331 | J11: -7373 | K11: -6485 | L11: -1071 | M11: -5093 | N11: -1864
B12: Fixed assets purchased | C12: -2748 | D12: -2247 | E12: -2723 | F12: -2760 | G12: -1998 | H12: -2445 | I12: -3307 | J12: -2107 | K12: -2161 | L12: -2579 | M12: -2201 | N12: -2237
B13: Fixed assets sold | C13: 3 | D13: 0 | E13: 0 | F13: 0 | G13: 0 | H13: 0 | I13: 0 | J13: 0 | K13: 0 | L13: 0 | M13: 0 | N13: 0
B14: Investments purchased | C14: -25046 | D14: -23923 | E14: -24577 | F14: -66410 | G14: -69159 | H14: -79410 | I14: -37482 | J14: -46738 | K14: -59951 | L14: -75800 | M14: -78118 | N14: -82753
B15: Investments sold | C15: 22385 | D15: 25253 | E15: 24980 | F15: 52048 | G15: 74003 | H15: 78098 | I15: 38861 | J15: 40381 | K15: 57356 | L15: 76722 | M15: 72956 | N15: 84888
... B27: Net Cash Flow | C27: 4118 | D27: 4417 | E27: 2330 | F27: -10072 | G27: -2754 | H27: -303 | I27: -919 | J27: 6065 | K27: -7242 | L27: -5299 | M27: 2613 | N27: 9669
